Workbook

Sheet V1.0
A1: Bauteilbenennung CAD | B1: Bauteil | C1: Teilenummer | D1: Version/Revisonsnr. | E1: Bauteilbenennung | G1: Werkstoff | H1: Beschichtung | I1: Dichte | J1: Material-stärke | K1: Anzahl | L1: Gewicht | M1: ∑
A2: =A1 -> Bauteilbenennung CAD | B2: =B1 -> Bauteil | C2: =C1 -> Teilenummer | D2: =D1 -> Version/Revisonsnr. | E2: =E1 -> Bauteilbenennung | F2: =F1 -> 0 | G2: =G1 -> Werkstoff | H2: =H1 -> Beschichtung | ... M2: =M1 -> ∑
A3: 111_222_333_00_M01_999_999_TESTPRODUCT_________________YYMMDD_CSI | B3: 111_222_333_00 | C3: =LEFT(A3,11) -> 111_222_333 | D3: =MID(A3,13,2) -> 00 | E3: =MID(A3,28,FIND("__",A3)-28) -> TESTPRODUCT | G3: ZSB | H3: - | I3: - | J3: - | K3: 1 | L3: - | M3: -
A4: 002_005_105_01_M01_999_999_SPACER_AH_1____________________251201_CSI | B4: 002_005_105_01 | C4: =LEFT(A4,11) -> 002_005_105 | D4: =MID(A4,13,2) -> 01 | E4: =MID(A4,28,FIND("__",A4)-28) -> SPACER_AH_1 | G4: EN AW 5754 H111 oder ähnliche | H4: Pulverbeschichtet - Schichtdicke 90 ±30 μm // RAL 9005 - SEIDENMATT/20±5%/60DEG | I4: 2700kg_m3 | J4: 12mm | K4: 1 | L4: 0.083 | M4: =K4*L4 -> 0.083
A5: 111_222_333_00_M01_999_999_ALU_PROFIL_____________________YYMMDD_CSI | B5: 111_222_333_00 | C5: =LEFT(A5,11) -> 111_222_333 | D5: =MID(A5,13,2) -> 00 | E5: =MID(A5,28,FIND("__",A5)-28) -> ALU_PROFIL | G5: Aluminium 6082 | I5: 2700kg_m3 | J5: 0 | K5: 1 | L5: 0.02 | M5: =K5*L5 -> 0.02
A6: 111_222_333_00_M01_999_999_BLECH__________________________YYMMDD_CSI | B6: 111_222_333_00 | C6: =LEFT(A6,11) -> 111_222_333 | D6: =MID(A6,13,2) -> 00 | E6: =MID(A6,28,FIND("__",A6)-28) -> BLECH | G6: Steel 1.4301 | H6: tauchbeschichtet | I6: 7850 | J6: 0 | K6: 2 | L6: 0.412 | M6: =K6*L6 -> 0.824
A7: 111_222_333_00_M01_999_999_DREHTEIL_______________________YYMMDD_CSI | B7: 111_222_333_00 | C7: =LEFT(A7,11) -> 111_222_333 | D7: =MID(A7,13,2) -> 00 | E7: =MID(A7,28,FIND("__",A7)-28) -> DREHTEIL | G7: Stahl V2A 1.4301 | H7: tauchbeschichtet | I7: 7850 | J7: 0 | K7: 5 | L7: 3.809 | M7: =K7*L7 -> 19.045
A8: 111_222_333_00_M01_999_999_GUSSTEIL_______________________YYMMDD_CSI | B8: 111_222_333_00 | C8: =LEFT(A8,11) -> 111_222_333 | D8: =MID(A8,13,2) -> 00 | E8: =MID(A8,28,FIND("__",A8)-28) -> GUSSTEIL | G8: Magnesium AZ91 | H8: tauchbeschichtet | I8: 1810kg_m3 | J8: 0 | K8: 1 | L8: 0.288 | M8: =K8*L8 -> 0.288
A9: 111_222_333_00_M01_999_999_KUNSTSTOFF_____________________YYMMDD_CSI | B9: 111_222_333_00 | C9: =LEFT(A9,11) -> 111_222_333 | D9: =MID(A9,13,2) -> 00 | E9: =MID(A9,28,FIND("__",A9)-28) -> KUNSTSTOFF | G9: PC/ABS | H9: lackierte Oberfläche | I9: 1130kg_m3 | J9: 2.5mm | K9: 1 | L9: 0.163 | M9: =K9*L9 -> 0.163
A10: 111_222_333_00_M01_999_999_STAHL_PROFIL___________________YYMMDD_CSI | B10: 111_222_333_00 | C10: =LEFT(A10,11) -> 111_222_333 | D10: =MID(A10,13,2) -> 00 | E10: =MID(A10,28,FIND("__",A10)-28) -> STAHL_PROFIL | G10: Stahl | I10: 7850 | J10: 0 | K10: 1 | L10: 0.043 | M10: =K10*L10 -> 0.043

Sheet Tabelle2
D2: Planned vehicles
D3: 10
D4: 45292 | I4: =D4+7 -> 45299 | J4: =F4+7 -> 7 | K4: =I4+7 -> 45306 | L4: =J4+7 -> 14 | M4: =K4+7 -> 45313 | N4: =L4+7 -> 21 | O4: =M4+7 -> 45320 | P4: =N4+7 -> 28 | Q4: =O4+7 -> 45327 | R4: =P4+7 -> 35 | ... AI4: =AG4+7 -> 45390
D5: 45296 | I5: =D5+7 -> 45303 | J5: =F5+7 -> 7 | K5: =I5+7 -> 45310 | L5: =J5+7 -> 14 | M5: =K5+7 -> 45317 | N5: =L5+7 -> 21 | O5: =M5+7 -> 45324 | P5: =N5+7 -> 28 | Q5: =O5+7 -> 45331 | R5: =P5+7 -> 35 | ... AI5: =AG5+7 -> 45394
A6: Materialnummer | B6: Artikelbezeichnung | C6: Anzahl pro Fahrzeug | D6: Bestand | E6: # lt AB | F6: geliefert | G6: Verbrauch | H6: Bestand EOW | I6: LT angekündigt | J6: geliefert | K6: LT angekündigt | L6: geliefert | M6: LT angekündigt | N6: geliefert | O6: LT angekündigt | P6: geliefert | Q6: LT angekündigt | R6: geliefert | S6: LT angekündigt | T6: geliefert | U6: LT angekündigt | V6: geliefert | W6: LT angekündigt | X6: geliefert | Y6: LT angekündigt | Z6: geliefert | AA6: LT angekündigt | AB6: geliefert | AC6: LT angekündigt | AD6: geliefert | AE6: LT angekündigt | AF6: geliefert | AG6: LT angekündigt | AH6: geliefert
C7: 1 | D7: 0 | E7: 5 | F7: 20 | G7: =C7*$D$3 -> 10 | H7: =D7+F7-G7 -> 10
C8: 2 | D8: 0 | E8: 10 | F8: 0 | G8: =C8*$D$3 -> 20 | H8: =D8+F8-G8 -> -20
C9: 5 | G9: =C9*$D$3 -> 50 | H9: =D9+F9-G9 -> -50
C10: 10 | G10: =C10*$D$3 -> 100 | H10: =D10+F10-G10 -> -100

Sheet Normteile
A1: Entwicklung
C2: Teilenummer | D2: Material- nummer | E2: Anzahl V2.1 | F2: Art | G2: Ausführung/Kommentar | H2: Gewinde | I2: Länge | J2: Norm | K2: Festigkeitsklasse | M2: Beschichtung | N2: Lieferant | O2: Bestellnummer | Q2: Link | R2: Bemerkung
L3: Anziehmoment | P3: Gewicht in kg
A6: 1 | B6: HALBRUNDKOPFSCHRAUBE_M4X12_ISO_7380-2_7380-2109VZ412 | C6: 999_000_001 | D6: - | E6: =SUMIF(#REF!,Normteile!C6,#REF!) -> #REF! | F6: Schraube | G6: HALBRUNDKOPFSCHRAUBE | H6: M4 | I6: 12 | J6: ISO 7380-2 | K6: 10.9 | L6: =IF(F6="Schraube",INDEX(Dropdown!$Q$5:$V$33,MATCH(Normteile!H6,Dropdown!$P$5:$P$33,0),MATCH(Normteile!K6,Dropdown!$Q$4:$V$4,0)),"-") -> 4.18 | M6: verzinkt | N6: Boellhoff | O6: 7380-2109VZ412 | P6: ? | Q6: https://eshop.boellhoff.de/en/Screws/Screws-with-internal-force-application/Hexagon-socket-button-head-screws-with-collar/Round-head-screws.html?force_sid=58b614ace06b4ef682e0097fd8d09e91&listtype=search&searchparam=2109VZ412
A7: 2 | B7: HALBRUNDKOPFSCHRAUBE_M5X16_ISO_7380-2_LFS109VZ516 | C7: 999_000_002 | D7: - | E7: =SUMIF(#REF!,Normteile!C7,#REF!) -> #REF! | F7: Schraube | G7: HALBRUNDKOPFSCHRAUBE | H7: M5 | I7: 16 | J7: ISO 7380-2 | K7: 10.9 | L7: =IF(F7="Schraube",INDEX(Dropdown!$Q$5:$V$33,MATCH(Normteile!H7,Dropdown!$P$5:$P$33,0),MATCH(Normteile!K7,Dropdown!$Q$4:$V$4,0)),"-") -> 8.48 | M7: verzinkt | N7: Boellhoff | O7: LFS109VZ516 | P7: ? | Q7: https://eshop.boellhoff.de/en/Screws/Screws-with-internal-force-application/Hexagon-socket-button-head-screws-with-collar/Round-head-screws.html?force_sid=58b614ace06b4ef682e0097fd8d09e91&listtype=search&searchparam=LFS109VZ516
A8: 3 | B8: HALBRUNDKOPFSCHRAUBE_M6X16_ISO_7380-2_7380-2109VZ616 | C8: 999_000_003 | D8: 91913988 | E8: =SUMIF(#REF!,Normteile!C8,#REF!) -> #REF! | F8: Schraube | G8: HALBRUNDKOPFSCHRAUBE | H8: M6 | I8: 16 | J8: ISO 7380-2 | K8: 10.9 | L8: =IF(F8="Schraube",INDEX(Dropdown!$Q$5:$V$33,MATCH(Normteile!H8,Dropdown!$P$5:$P$33,0),MATCH(Normteile!K8,Dropdown!$Q$4:$V$4,0)),"-") -> 14.41 | M8: verzinkt | N8: Boellhoff | O8: 7380-2109VZ616 | P8: 0.006 | Q8: https://eshop.boellhoff.de/en/Screws/Screws-with-internal-force-application/Hexagon-socket-button-head-screws-with-collar/Round-head-screws.html?force_sid=58b614ace06b4ef682e0097fd8d09e91&listtype=search&searchparam=2109VZ616
A9: 4 | B9: HALBRUNDKOPFSCHRAUBE_M8X25_ISO_7380-2_7380-2109VZ825 | C9: 999_000_004 | D9: 91908668 | E9: =SUMIF(#REF!,Normteile!C9,#REF!) -> #REF! | F9: Schraube | G9: HALBRUNDKOPFSCHRAUBE | H9: M8 | I9: 25 | J9: ISO 7380-2 | K9: 10.9 | L9: =IF(F9="Schraube",INDEX(Dropdown!$Q$5:$V$33,MATCH(Normteile!H9,Dropdown!$P$5:$P$33,0),MATCH(Normteile!K9,Dropdown!$Q$4:$V$4,0)),"-") -> 35.06 | M9: verzinkt | N9: Boellhoff | O9: 2109VZ825 | P9: 0.015 | Q9: https://eshop.boellhoff.de/en/Screws/Screws-with-internal-force-application/Hexagon-socket-button-head-screws-with-collar/Round-head-screws.html?force_sid=58b614ace06b4ef682e0097fd8d09e91&listtype=search&searchparam=2109VZ616
A10: 5 | B10: HAMMERMUTTER_8_M6_ITEM_0062606 | C10: 999_000_005 | D10: - | E10: =SUMIF(#REF!,Normteile!C10,#REF!) -> #REF! | F10: ITEM | G10: Hammermutter | H10: M6 | L10: =IF(F10="Schraube",INDEX(Dropdown!$Q$5:$V$33,MATCH(Normteile!H10,Dropdown!$P$5:$P$33,0),MATCH(Normteile!K10,Dropdown!$Q$4:$V$4,0)),"-") -> - | M10: verzinkt | N10: ITEM | O10: 62606 | P10: ? | Q10: https://www.item24.com/de-de/hammermutter-8-m6-verzinkt-62606/ | R10: Serie ITEM 8
A11: 6 | B11: IGUS_IGLIDUR_GFM-04050-04 | C11: 999_000_006 | D11: - | E11: =SUMIF(#REF!,Normteile!C11,#REF!) -> #REF! | F11: Igus | G11: Gleitlager mit Bund | L11: =IF(F11="Schraube",INDEX(Dropdown!$Q$5:$V$33,MATCH(Normteile!H11,Dropdown!$P$5:$P$33,0),MATCH(Normteile!K11,Dropdown!$Q$4:$V$4,0)),"-") -> - | N11: Igus | P11: ? | Q11: https://www.igus.de/product/64?artNr=GFM-04050-04&utm_term=&utm_campaign=DE%7CE-Chains%7CGoogle+Ads%7CMax-Performance%7C03-Orders%7Ce-chains+Bestsellers%7CQ2/2022&utm_source=adwords&utm_medium=ppc&hsa_acc=9293631960&hsa_cam=16818505652&hsa_grp=&hsa_ad=&hsa_src=x&hsa_tgt=&hsa_kw=&hsa_mt=&hsa_net=adwords&hsa_ver=3&gclid=EAIaIQobChMI0fTA8_Ss-AIVFY1oCR2fpwJQEAAYASAAEgIiy_D_BwE
A12: 7 | B12: PASSSCHRAUBE_6_M5_10_ISO_7379 | C12: 999_000_007 | D12: - | E12: =SUMIF(#REF!,Normteile!C12,#REF!) -> #REF! | F12: Schraube | G12: Passschraube | H12: M5 | I12: 10 | J12: ISO 7379 | L12: =IF(F12="Schraube",INDEX(Dropdown!$Q$5:$V$33,MATCH(Normteile!H12,Dropdown!$P$5:$P$33,0),MATCH(Normteile!K12,Dropdown!$Q$4:$V$4,0)),"-") -> #N/A | P12: 0.006
A13: 8 | B13: PASSSCHRAUBE_ISO_7379_8_M6_30_NI | C13: 999_000_008 | D13: 91946427 | E13: =SUMIF(#REF!,Normteile!C13,#REF!) -> #REF! | F13: Schraube | G13: Passschraube | H13: M6 | I13: 30 | J13: ISO 7379 | L13: =IF(F13="Schraube",INDEX(Dropdown!$Q$5:$V$33,MATCH(Normteile!H13,Dropdown!$P$5:$P$33,0),MATCH(Normteile!K13,Dropdown!$Q$4:$V$4,0)),"-") -> #N/A | N13: Ganter Norm | O13: ISO 7379-8-M6-30-NI | P13: 0.019 | Q13: https://www.ganternorm.com/de/produkte/3.2-Befestigen-Positionieren-Nivellieren-mit-Schraub-Klemm-und-Auflageelementen/Augenschrauben-Passschrauben-Druckschrauben/ISO-7379-Edelstahl-Passschrauben#d1%3Dc(8)%3Bd2%3Du(0c49c7b3-a2d5-4127-b6ac-792d414b1606)%3Bl1%3Dc(30)%3BWerkstoff%3Du(4ffaa763-f739-4917-9edb-5c7ca96d4057)
A14: 9 | B14: SCHAFTSCHRAUBE_M10_20_DIN_427_427143051020 | C14: 999_000_009 | D14: - | E14: =SUMIF(#REF!,Normteile!C14,#REF!) -> #REF! | F14: Schraube | G14: Schaftschraube | H14: M10 | I14: 20 | J14: DIN 427 | L14: =IF(F14="Schraube",INDEX(Dropdown!$Q$5:$V$33,MATCH(Normteile!H14,Dropdown!$P$5:$P$33,0),MATCH(Normteile!K14,Dropdown!$Q$4:$V$4,0)),"-") -> #N/A | N14: Boellhoff | O14: 427143051020 | P14: ? | Q14: https://eshop.boellhoff.de/Schrauben/Schrauben-mit-Innenkraftangriff/Zylinderschrauben/Schaftschrauben-Edelstahl-1-4305-M-10-20-50-Stk.html?force_sid=58b614ace06b4ef682e0097fd8d09e91&redirected=1
A15: 10 | B15: SCHEIBE_M10_DIN_125A_125VZ10,5 | C15: 999_000_010 | D15: 91908676 | E15: =SUMIF(#REF!,Normteile!C15,#REF!) -> #REF! | F15: Scheibe | H15: M10 | J15: DIN 125 A | L15: =IF(F15="Schraube",INDEX(Dropdown!$Q$5:$V$33,MATCH(Normteile!H15,Dropdown!$P$5:$P$33,0),MATCH(Normteile!K15,Dropdown!$Q$4:$V$4,0)),"-") -> - | M15: verzinkt | N15: Boellhoff | O15: 125VZ10,5 | P15: 0.004 | Q15: https://eshop.boellhoff.de/Scheiben/Unterlegscheiben/Scheiben/Scheiben-Stahl-140-HV-verzinkt-10-5-500-Stk.html?force_sid=58b614ace06b4ef682e0097fd8d09e91&redirected=1
A16: 11 | B16: SCHEIBE_M10_DIN_9021_9021VZ10,5 | C16: 999_000_011 | D16: 91908679 | E16: =SUMIF(#REF!,Normteile!C16,#REF!) -> #REF! | F16: Scheibe | H16: M10 | J16: DIN 9021 | L16: =IF(F16="Schraube",INDEX(Dropdown!$Q$5:$V$33,MATCH(Normteile!H16,Dropdown!$P$5:$P$33,0),MATCH(Normteile!K16,Dropdown!$Q$4:$V$4,0)),"-") -> - | M16: verzinkt | N16: Boellhoff | O16: 9021VZ10,5 | P16: 0.012 | Q16: https://eshop.boellhoff.de/Scheiben/Unterlegscheiben/Scheiben/Scheiben-Stahl-140-HV-verzinkt-10-5-200-Stk.html?force_sid=58b614ace06b4ef682e0097fd8d09e91&redirected=1
A17: 12 | B17: SCHEIBE_M17_DIN_125A_125VZ17 | C17: 999_000_012 | D17: - | E17: =SUMIF(#REF!,Normteile!C17,#REF!) -> #REF! | F17: Scheibe | H17: M17 | J17: DIN 125 A | L17: =IF(F17="Schraube",INDEX(Dropdown!$Q$5:$V$33,MATCH(Normteile!H17,Dropdown!$P$5:$P$33,0),MATCH(Normteile!K17,Dropdown!$Q$4:$V$4,0)),"-") -> - | M17: verzinkt | N17: Boellhoff | O17: 125VZ17 | P17: ? | Q17: https://eshop.boellhoff.de/Scheiben/Unterlegscheiben/Scheiben/Scheiben-Stahl-140-HV-verzinkt-17-200-Stk.html?force_sid=58b614ace06b4ef682e0097fd8d09e91&redirected=1
A18: 13 | B18: SCHEIBE_M5_DIN_125A_125VZ5,3 | C18: 999_000_013 | D18: 91908657 | E18: =SUMIF(#REF!,Normteile!C18,#REF!) -> #REF! | F18: Scheibe | H18: M5 | J18: DIN 125 A | L18: =IF(F18="Schraube",INDEX(Dropdown!$Q$5:$V$33,MATCH(Normteile!H18,Dropdown!$P$5:$P$33,0),MATCH(Normteile!K18,Dropdown!$Q$4:$V$4,0)),"-") -> - | M18: verzinkt | N18: Boellhoff | O18: 125VZ5,3 | P18: 0.0004434 | Q18: https://eshop.boellhoff.de/Scheiben/Unterlegscheiben/Scheiben/Scheiben-Stahl-140-HV-verzinkt-5-3-1000-Stk-/.html?force_sid=58b614ace06b4ef682e0097fd8d09e91&redirected=1
A19: 14 | B19: SCHEIBE_M6_DIN_125A_125VZ6,4 | C19: 999_000_014 | D19: 91908690 | E19: =SUMIF(#REF!,Normteile!C19,#REF!) -> #REF! | F19: Scheibe | H19: M6 | J19: DIN 125 A | L19: =IF(F19="Schraube",INDEX(Dropdown!$Q$5:$V$33,MATCH(Normteile!H19,Dropdown!$P$5:$P$33,0),MATCH(Normteile!K19,Dropdown!$Q$4:$V$4,0)),"-") -> - | M19: verzinkt | N19: Boellhoff | O19: 125VZ6,4 | P19: 0.001 | Q19: https://eshop.boellhoff.de/Scheiben/Unterlegscheiben/Scheiben/Scheiben-Stahl-140-HV-verzinkt-6-4-1000-Stk.html?force_sid=58b614ace06b4ef682e0097fd8d09e91&redirected=1
A20: 15 | B20: SCHEIBE_M6_DIN_9021_9021VZ6,4 | C20: 999_000_015 | D20: - | E20: =SUMIF(#REF!,Normteile!C20,#REF!) -> #REF! | F20: Scheibe | H20: M6 | J20: DIN 9021 | L20: =IF(F20="Schraube",INDEX(Dropdown!$Q$5:$V$33,MATCH(Normteile!H20,Dropdown!$P$5:$P$33,0),MATCH(Normteile!K20,Dropdown!$Q$4:$V$4,0)),"-") -> - | M20: verzinkt | N20: Boellhoff | O20: 9021VZ6,4 | P20: ? | Q20: https://eshop.boellhoff.de/Scheiben/Unterlegscheiben/Scheiben/Scheiben-Stahl-140-HV-verzinkt-6-4-1000-Stk-/.html?force_sid=58b614ace06b4ef682e0097fd8d09e91&redirected=1
A21: 16 | B21: SCHEIBE_M8_DIN_125A_125VZ8,4 | C21: 999_000_016 | D21: 91908654 | E21: =SUMIF(#REF!,Normteile!C21,#REF!) -> #REF! | F21: Scheibe | H21: M8 | J21: DIN 125 A | L21: =IF(F21="Schraube",INDEX(Dropdown!$Q$5:$V$33,MATCH(Normteile!H21,Dropdown!$P$5:$P$33,0),MATCH(Normteile!K21,Dropdown!$Q$4:$V$4,0)),"-") -> - | M21: verzinkt | N21: Boellhoff | O21: 125VZ8,4 | P21: 0.002 | Q21: https://eshop.boellhoff.de/Scheiben/Unterlegscheiben/Scheiben/Scheiben-Stahl-140-HV-verzinkt-8-4-1000-Stk.html?force_sid=58b614ace06b4ef682e0097fd8d09e91&redirected=1
A22: 17 | B22: SCHEIBE_M8_DIN_9021_9021VZ8,4 | C22: 999_000_017 | D22: 91913974 | E22: =SUMIF(#REF!,Normteile!C22,#REF!) -> #REF! | F22: Scheibe | H22: M8 | J22: DIN 9021 | L22: =IF(F22="Schraube",INDEX(Dropdown!$Q$5:$V$33,MATCH(Normteile!H22,Dropdown!$P$5:$P$33,0),MATCH(Normteile!K22,Dropdown!$Q$4:$V$4,0)),"-") -> - | M22: verzinkt | N22: Boellhoff | O22: 9021VZ8,4 | P22: 0.006 | Q22: https://eshop.boellhoff.de/Scheiben/Unterlegscheiben/Scheiben/Scheiben-Stahl-140-HV-verzinkt-8-4-500-Stk.html?force_sid=58b614ace06b4ef682e0097fd8d09e91&redirected=1
A23: 18 | D23: 0
A24: 19 | B24: SECHSKANTMUTTER_M10_ISO_4032_403210VZD10 | C24: 999_000_019 | D24: 91908677 | E24: =SUMIF(#REF!,Normteile!C24,#REF!) -> #REF! | F24: Mutter | G24: Sechskantmutter | H24: M10 | J24: ISO 4032 | K24: 10 | L24: =IF(F24="Schraube",INDEX(Dropdown!$Q$5:$V$33,MATCH(Normteile!H24,Dropdown!$P$5:$P$33,0),MATCH(Normteile!K24,Dropdown!$Q$4:$V$4,0)),"-") -> - | M24: verzinkt | N24: Boellhoff | O24: 403210VZD10 | P24: ? | Q24: https://eshop.boellhoff.de/Muttern/Muttern-ohne-Sicherungsfunktion/Sechskantmuttern/Sechskantmuttern-Stahl-10-verzinkt-dickschichtpassiviert-VZD-M-10-500-Stk.html?force_sid=58b614ace06b4ef682e0097fd8d09e91&redirected=1
A25: 20 | B25: SECHSKANTMUTTER_M16_DIN_982_98210VZ16 | C25: 999_000_020 | D25: - | E25: =SUMIF(#REF!,Normteile!C25,#REF!) -> #REF! | F25: Mutter | G25: Sechskantmutter selbstsichernd | H25: M6 | J25: DIN 982 | K25: 10 | L25: =IF(F25="Schraube",INDEX(Dropdown!$Q$5:$V$33,MATCH(Normteile!H25,Dropdown!$P$5:$P$33,0),MATCH(Normteile!K25,Dropdown!$Q$4:$V$4,0)),"-") -> - | M25: verzinkt | N25: Boellhoff | O25: 98210VZ16 | P25: ? | Q25: https://eshop.boellhoff.de/Muttern/Muttern-mit-Sicherungsfunktion/Sechskantmuttern/Sechskantmuttern-Stahl-10-verzinkt-M-16-100-Stk.html?force_sid=58b614ace06b4ef682e0097fd8d09e91&redirected=1
A26: 21 | B26: SECHSKANTMUTTER_M4_ISO_4032_40328VZ4 | C26: 999_000_021 | D26: - | E26: =SUMIF(#REF!,Normteile!C26,#REF!) -> #REF! | F26: Mutter | G26: Sechskantmutter | H26: M4 | J26: ISO 4032 | K26: 8 | L26: =IF(F26="Schraube",INDEX(Dropdown!$Q$5:$V$33,MATCH(Normteile!H26,Dropdown!$P$5:$P$33,0),MATCH(Normteile!K26,Dropdown!$Q$4:$V$4,0)),"-") -> - | M26: verzinkt | N26: Boellhoff | O26: 40328VZ4 | P26: 0.0008528 | Q26: https://eshop.boellhoff.de/Muttern/Muttern-ohne-Sicherungsfunktion/Sechskantmuttern/Sechskantmuttern-Stahl-8-verzinkt-M-4-1000-Stk-/.html?force_sid=58b614ace06b4ef682e0097fd8d09e91&redirected=1
A27: 22 | B27: SECHSKANTMUTTER_M5_DIN_982_9828VZ5 | C27: 999_000_022 | D27: - | E27: =SUMIF(#REF!,Normteile!C27,#REF!) -> #REF! | F27: Mutter | G27: Sechskantmutter selbstsichernd | H27: M5 | J27: DIN 982 | K27: 8 | L27: =IF(F27="Schraube",INDEX(Dropdown!$Q$5:$V$33,MATCH(Normteile!H27,Dropdown!$P$5:$P$33,0),MATCH(Normteile!K27,Dropdown!$Q$4:$V$4,0)),"-") -> - | M27: verzinkt | N27: Boellhoff | O27: 9828VZ5 | P27: 0.002 | Q27: https://eshop.boellhoff.de/Muttern/Muttern-mit-Sicherungsfunktion/Sechskantmuttern/Sechskantmuttern-Stahl-8-verzinkt-M-5-1000-Stk-/-2.html?force_sid=58b614ace06b4ef682e0097fd8d09e91&redirected=1
A28: 23 | B28: SECHSKANTMUTTER_M5_ISO_4032_40328VZ5 | C28: 999_000_023 | D28: 91914015 | E28: =SUMIF(#REF!,Normteile!C28,#REF!) -> #REF! | F28: Mutter | G28: Sechskantmutter | H28: M5 | J28: ISO 4032 | K28: 8 | L28: =IF(F28="Schraube",INDEX(Dropdown!$Q$5:$V$33,MATCH(Normteile!H28,Dropdown!$P$5:$P$33,0),MATCH(Normteile!K28,Dropdown!$Q$4:$V$4,0)),"-") -> - | M28: verzinkt | N28: Boellhoff | O28: 40328VZ5 | P28: 0.002 | Q28: https://eshop.boellhoff.de/Muttern/Muttern-ohne-Sicherungsfunktion/Sechskantmuttern/Sechskantmuttern-Stahl-8-verzinkt-M-5-1000-Stk-/.html?force_sid=58b614ace06b4ef682e0097fd8d09e91&redirected=1
A29: 24 | B29: SECHSKANTMUTTER_M6_DIN982_9828VZ6 | C29: 999_000_024 | D29: 91946429 | E29: =SUMIF(#REF!,Normteile!C29,#REF!) -> #REF! | F29: Mutter | G29: Sechskantmutter selbstsichernd | H29: M6 | J29: DIN 982 | K29: 8 | L29: =IF(F29="Schraube",INDEX(Dropdown!$Q$5:$V$33,MATCH(Normteile!H29,Dropdown!$P$5:$P$33,0),MATCH(Normteile!K29,Dropdown!$Q$4:$V$4,0)),"-") -> - | M29: verzinkt | N29: Boellhoff | O29: 9828VZ6 | P29: 0.003 | Q29: https://eshop.boellhoff.de/Muttern/Muttern-mit-Sicherungsfunktion/Sechskantmuttern/Sechskantmuttern-Stahl-8-verzinkt-M-6-1000-Stk-/-2.html?force_sid=58b614ace06b4ef682e0097fd8d09e91&redirected=1
A30: 25 | B30: SECHSKANTMUTTER_M6_ISO_4032_403210VZ6 | C30: 999_000_025 | D30: - | E30: =SUMIF(#REF!,Normteile!C30,#REF!) -> #REF! | F30: Mutter | G30: Sechskantmutter | H30: M6 | J30: ISO 4032 | K30: 10 | L30: =IF(F30="Schraube",INDEX(Dropdown!$Q$5:$V$33,MATCH(Normteile!H30,Dropdown!$P$5:$P$33,0),MATCH(Normteile!K30,Dropdown!$Q$4:$V$4,0)),"-") -> - | M30: verzinkt | N30: Boellhoff | O30: 403210VZ6 | P30: ? | Q30: https://eshop.boellhoff.de/Muttern/Muttern-ohne-Sicherungsfunktion/Sechskantmuttern/Sechskantmuttern-Stahl-10-verzinkt-M-6-1000-Stk-/.html?force_sid=58b614ace06b4ef682e0097fd8d09e91&redirected=1
A31: 26 | B31: SECHSKANTMUTTER_M8_DIN_982_9828VZ8 | C31: 999_000_026 | D31: 91913977 | E31: =SUMIF(#REF!,Normteile!C31,#REF!) -> #REF! | F31: Mutter | G31: Sechskantmutter | H31: M8 | J31: DIN 982 | K31: 8 | L31: =IF(F31="Schraube",INDEX(Dropdown!$Q$5:$V$33,MATCH(Normteile!H31,Dropdown!$P$5:$P$33,0),MATCH(Normteile!K31,Dropdown!$Q$4:$V$4,0)),"-") -> - | M31: verzinkt | N31: Boellhoff | O31: 9828VZ8 | P31: 0.007 | Q31: https://eshop.boellhoff.de/Muttern/Muttern-mit-Sicherungsfunktion/Sechskantmuttern/Sechskantmuttern-Stahl-8-verzinkt-M-8-1000-Stk-/.html?force_sid=58b614ace06b4ef682e0097fd8d09e91&redirected=1
A32: 27 | B32: SECHSKANTSCHRAUBE_M10X30_DIN933_9338.8VZ1030 | C32: 999_000_027 | D32: 91914038 | E32: =SUMIF(#REF!,Normteile!C32,#REF!) -> #REF! | F32: Schraube | G32: Sechskantschraube | H32: M10 | I32: 30 | J32: DIN 933 | K32: 8.8 | L32: =IF(F32="Schraube",INDEX(Dropdown!$Q$5:$V$33,MATCH(Normteile!H32,Dropdown!$P$5:$P$33,0),MATCH(Normteile!K32,Dropdown!$Q$4:$V$4,0)),"-") -> 49 | M32: verzinkt | N32: Boellhoff | O32: 9338.8VZ1030 | P32: 0.031 | Q32: https://eshop.boellhoff.de/Schrauben/Schrauben-mit-Aussenkraftangriff/Sechskantschrauben/Sechskantschrauben-Stahl-8-8-verzinkt-M-10-30-200-Stk.html?force_sid=58b614ace06b4ef682e0097fd8d09e91&redirected=1
A33: 28 | B33: SECHSKANTSCHRAUBE_M10X60_DIN933_9338.8VZ1060 | C33: 999_000_028 | D33: 91946430 | E33: =SUMIF(#REF!,Normteile!C33,#REF!) -> #REF! | F33: Schraube | G33: Sechskantschraube | H33: M10 | I33: 60 | J33: DIN 933 | K33: 8.8 | L33: =IF(F33="Schraube",INDEX(Dropdown!$Q$5:$V$33,MATCH(Normteile!H33,Dropdown!$P$5:$P$33,0),MATCH(Normteile!K33,Dropdown!$Q$4:$V$4,0)),"-") -> 49 | M33: verzinkt | N33: Boellhoff | O33: 9338.8VZ1060 | P33: 0.049 | Q33: https://eshop.boellhoff.de/Schrauben/Schrauben-mit-Aussenkraftangriff/Sechskantschrauben/Sechskantschrauben-Stahl-8-8-verzinkt-M-10-60-100-Stk-/-1.html?force_sid=58b614ace06b4ef682e0097fd8d09e91&redirected=1
A34: 29 | B34: SECHSKANTSCHRAUBE_M16X180_DIN931_9318.8VZ16180 | C34: 999_000_029 | D34: - | E34: =SUMIF(#REF!,Normteile!C34,#REF!) -> #REF! | F34: Schraube | G34: Sechskantschraube | H34: M16 | I34: 180 | J34: DIN 931 | K34: 8.8 | L34: =IF(F34="Schraube",INDEX(Dropdown!$Q$5:$V$33,MATCH(Normteile!H34,Dropdown!$P$5:$P$33,0),MATCH(Normteile!K34,Dropdown!$Q$4:$V$4,0)),"-") -> 215 | M34: verzinkt | N34: Boellhoff | O34: 9318.8VZ16180 | P34: ? | Q34: https://eshop.boellhoff.de/Schrauben/Schrauben-mit-Aussenkraftangriff/Sechskantschrauben/Sechskantschrauben-Stahl-8-8-verzinkt-M-16-180-25-Stk.html?force_sid=58b614ace06b4ef682e0097fd8d09e91&redirected=1
A35: 30 | B35: SECHSKANTSCHRAUBE_M5x40_DIN933_9338.8VZ540 | C35: 999_000_030 | D35: 91908682 | E35: =SUMIF(#REF!,Normteile!C35,#REF!) -> #REF! | F35: Schraube | G35: Sechskantschraube | H35: M5 | I35: 40 | J35: DIN 933 | K35: 8.8 | L35: =IF(F35="Schraube",INDEX(Dropdown!$Q$5:$V$33,MATCH(Normteile!H35,Dropdown!$P$5:$P$33,0),MATCH(Normteile!K35,Dropdown!$Q$4:$V$4,0)),"-") -> 6.03 | M35: verzinkt | N35: Boellhoff | O35: 9338.8VZ540 | P35: 0.008 | Q35: https://eshop.boellhoff.de/Schrauben/Schrauben-mit-Aussenkraftangriff/Sechskantschrauben/Sechskantschrauben-Stahl-8-8-verzinkt-M-5-40-200-Stk-/.html?force_sid=58b614ace06b4ef682e0097fd8d09e91&redirected=1
A36: 31 | B36: SECHSKANTSCHRAUBE_M6X12_DIN933_9338.8VZ612 | C36: 999_000_031 | D36: - | E36: =SUMIF(#REF!,Normteile!C36,#REF!) -> #REF! | F36: Schraube | G36: Sechskantschraube | H36: M6 | I36: 12 | J36: DIN 933 | K36: 8.8 | L36: =IF(F36="Schraube",INDEX(Dropdown!$Q$5:$V$33,MATCH(Normteile!H36,Dropdown!$P$5:$P$33,0),MATCH(Normteile!K36,Dropdown!$Q$4:$V$4,0)),"-") -> 10.25 | M36: verzinkt | N36: Boellhoff | O36: 9338.8VZ612 | P36: ? | Q36: https://eshop.boellhoff.de/Schrauben/Schrauben-mit-Aussenkraftangriff/Sechskantschrauben/Sechskantschrauben-Stahl-8-8-verzinkt-M-6-12-500-Stk.html?force_sid=58b614ace06b4ef682e0097fd8d09e91&redirected=1
A37: 32 | B37: SECHSKANTSCHRAUBE_M6X25_DIN933_9338.8VZ620 | C37: 999_000_032 | D37: 91914024 | E37: =SUMIF(#REF!,Normteile!C37,#REF!) -> #REF! | F37: Schraube | G37: Sechskantschraube | H37: M6 | I37: 25 | J37: DIN 933 | K37: 8.8 | L37: =IF(F37="Schraube",INDEX(Dropdown!$Q$5:$V$33,MATCH(Normteile!H37,Dropdown!$P$5:$P$33,0),MATCH(Normteile!K37,Dropdown!$Q$4:$V$4,0)),"-") -> 10.25 | M37: verzinkt | N37: Boellhoff | O37: 9338.8VZ620 | P37: 0.008 | Q37: https://eshop.boellhoff.de/Schrauben/Schrauben-mit-Aussenkraftangriff/Sechskantschrauben/Sechskantschrauben-Stahl-8-8-verzinkt-M-6-20-500-Stk.html?force_sid=58b614ace06b4ef682e0097fd8d09e91&redirected=1
A38: 33 | B38: SECHSKANTSCHRAUBE_M6x40_DIN933_9338.8VZ640 | C38: 999_000_033 | D38: 91907563 | E38: =SUMIF(#REF!,Normteile!C38,#REF!) -> #REF! | F38: Schraube | G38: Sechskantschraube | H38: M6 | I38: 40 | J38: DIN 933 | K38: 8.8 | L38: =IF(F38="Schraube",INDEX(Dropdown!$Q$5:$V$33,MATCH(Normteile!H38,Dropdown!$P$5:$P$33,0),MATCH(Normteile!K38,Dropdown!$Q$4:$V$4,0)),"-") -> 10.25 | M38: verzinkt | N38: Boellhoff | O38: 9338.8VZ640 | P38: 0.011 | Q38: https://eshop.boellhoff.de/Schrauben/Schrauben-mit-Aussenkraftangriff/Sechskantschrauben/Sechskantschrauben-Stahl-8-8-verzinkt-M-6-40-200-Stk-/.html?force_sid=58b614ace06b4ef682e0097fd8d09e91&redirected=1
A39: 34 | B39: SECHSKANTSCHRAUBE_M6X55_DIN933_9338.8VZ655 | C39: 999_000_034 | D39: 91907564 | E39: =SUMIF(#REF!,Normteile!C39,#REF!) -> #REF! | F39: Schraube | G39: Sechskantschraube | H39: M6 | I39: 55 | J39: DIN 933 | K39: 8.8 | L39: =IF(F39="Schraube",INDEX(Dropdown!$Q$5:$V$33,MATCH(Normteile!H39,Dropdown!$P$5:$P$33,0),MATCH(Normteile!K39,Dropdown!$Q$4:$V$4,0)),"-") -> 10.25 | M39: verzinkt | N39: Boellhoff | O39: 9338.8VZ655 | P39: 0.015 | Q39: https://eshop.boellhoff.de/Schrauben/Schrauben-mit-Aussenkraftangriff/Sechskantschrauben/Sechskantschrauben-Stahl-8-8-verzinkt-M-6-55-200-Stk-/.html?force_sid=58b614ace06b4ef682e0097fd8d09e91&redirected=1
A40: 35 | B40: SECHSKANTSCHRAUBE_M6X65_DIN933_9338.8VZ665 | C40: 999_000_035 | D40: - | E40: =SUMIF(#REF!,Normteile!C40,#REF!) -> #REF! | F40: Schraube | G40: Sechskantschraube | H40: M6 | I40: 65 | J40: DIN 933 | K40: 8.8 | L40: =IF(F40="Schraube",INDEX(Dropdown!$Q$5:$V$33,MATCH(Normteile!H40,Dropdown!$P$5:$P$33,0),MATCH(Normteile!K40,Dropdown!$Q$4:$V$4,0)),"-") -> 10.25 | M40: verzinkt | N40: Boellhoff | O40: 9338.8VZ665 | P40: ? | Q40: https://eshop.boellhoff.de/Schrauben/Schrauben-mit-Aussenkraftangriff/Sechskantschrauben/Sechskantschrauben-Stahl-8-8-verzinkt-M-6-65-200-Stk-/.html?force_sid=58b614ace06b4ef682e0097fd8d09e91&redirected=1
A41: 36 | B41: SECHSKANTSCHRAUBE_M6X75_DIN933_9338.8VZ675 | C41: 999_000_036 | D41: - | E41: =SUMIF(#REF!,Normteile!C41,#REF!) -> #REF! | F41: Schraube | G41: Sechskantschraube | H41: M6 | I41: 75 | J41: DIN 933 | K41: 8.8 | L41: =IF(F41="Schraube",INDEX(Dropdown!$Q$5:$V$33,MATCH(Normteile!H41,Dropdown!$P$5:$P$33,0),MATCH(Normteile!K41,Dropdown!$Q$4:$V$4,0)),"-") -> 10.25 | M41: verzinkt | N41: Boellhoff | O41: 9338.8VZ675 | P41: ? | Q41: https://eshop.boellhoff.de/Schrauben/Schrauben-mit-Aussenkraftangriff/Sechskantschrauben/Sechskantschrauben-Stahl-8-8-verzinkt-M-6-75-200-Stk.html?force_sid=58b614ace06b4ef682e0097fd8d09e91&redirected=1
A42: 37 | B42: SECHSKANTSCHRAUBE_M8X65_DIN933_9338.8VZ865 | C42: 999_000_037 | D42: 91914023 | E42: =SUMIF(#REF!,Normteile!C42,#REF!) -> #REF! | F42: Schraube | G42: Sechskantschraube | H42: M8 | I42: 65 | J42: DIN 933 | K42: 8.8 | L42: =IF(F42="Schraube",INDEX(Dropdown!$Q$5:$V$33,MATCH(Normteile!H42,Dropdown!$P$5:$P$33,0),MATCH(Normteile!K42,Dropdown!$Q$4:$V$4,0)),"-") -> 24.93 | M42: verzinkt | N42: Boellhoff | O42: 9338.8VZ865 | P42: 0.032 | Q42: https://eshop.boellhoff.de/Schrauben/Schrauben-mit-Aussenkraftangriff/Sechskantschrauben/Sechskantschrauben-Stahl-8-8-verzinkt-M-8-65-200-Stk-/.html?force_sid=58b614ace06b4ef682e0097fd8d09e91&redirected=1
...

Sheet Dropdown
L1: Multiplikationsfaktor Ersatzteilbedarf | Q1: Anzugsmoment / Anzugsdrehmoment Tabelle für Regelgewinde
B2: Freigabestand | D2: Werkstoff | F2: Beschichtung | H2: Fertigungsverfahren | K2: A teil - Werkzeuglastige Auftragsfertigung nach Zeichnung / Lieferantenwechsel Schwierig | L2: Benennung | M2: Faktor
B3: Arbeitsstand | D3: S235JR | F3: KTL - Schichtdicke 25 ±5 μm | H3: Tiefziehteil | K3: B teil - Nicht-Werkzeuglastige Auftragsfertigung nach Zeichnung / Liefrantenwechsel möglich | L3: - | M3: - | P3: Gewindegroesse | Q3: Drehmoment in (Nm)
B4: Berechnungsstand | D4: S235JRH | F4: Im ZSB | H4: Kantteil | K4: C teil - Kritische Kaufteile / nur bei wenigen Lieferanten vorhanden / ggfs. Lieferengpass / Verhandlung kaum realisierbar | L4: Normteile | M4: 0.1 | P4: Festigkeitsklasse | Q4: 4.6 | R4: 5.6 | S4: 6.8 | T4: 8.8 | U4: 10.9 | V4: 12.9
B5: Anfragestand | D5: S355 | F5: siehe Kauf-/Normteil | H5: Laserteil | K5: D teil - Unkritische Kaufteile / bei mehreren Lieferanten vorhanden / kein lieferengpass / Verhandlung möglich | L5: Montageausschuss | M5: 0.02 | P5: M2 | Q5: 0.13 | R5: 0.16 | S5: 0.26 | T5: 0.35 | U5: 0.49 | V5: 0.59
B6: Prototypenstand | D6: S355JOH | F6: - | H6: Gussteil | K6: E teil - Norm teile - üppig verügbar | L6: Fahrradkomponente | M6: 0.1 | P6: M2,5 | Q6: 0.27 | R6: 0.34 | S6: 0.54 | T6: 0.72 | U6: 1.01 | V6: 1.21
B7: Freigabestand | D7: HC420LA | F7: Lackiert - Schichtdicke 100 ±20 μm - Weißaluminium, RAL 9006 (seidenmatt) | H7: Profilteil | L7: Anbauteile Kategorie 1 | M7: 0.1 | P7: M3 | Q7: 0.48 | R7: 0.6 | S7: 0.96 | T7: 1.28 | U7: 1.8 | V7: 2.16
B8: Kauf-/Normteil | D8: E295/1.0050 | F8: ZE + KTL - Schichtdicke 25 ±5 μm | H8: Dreh-/Frästeil | K8: Der Buschstabe A-D ist unter anderem Teil des Bauteilnamens im CAD. | L8: Anbauteile Kategorie 2 | M8: 0.3 | P8: M4 | Q8: 1.12 | R8: 1.39 | S8: 2.23 | T8: 2.97 | U8: 4.18 | V8: 5.02
B9: HOLD | D9: 1.4301 | F9: Harteloxiert - Schichtdicke 25 ±5 μm - Weißaluminium, RAL 9006 (seidenmatt) | H9: Stanz-/Biegeteil | L9: Anbauteile Kategorie 3 | M9: 0.5 | P9: M5 | Q9: 2.26 | R9: 2.83 | S9: 4.52 | T9: 6.03 | U9: 8.48 | V9: 10.18
D10: 1.4310 | F10: Pulverbeschichtet - Schichtdicke 90 ±30 μm - Graphitschwarz, RAL 9011 (seidenmatt) | H10: Thermoformingteil | P10: M6 | Q10: 3.84 | R10: 4.8 | S10: 7.69 | T10: 10.25 | U10: 14.41 | V10: 17.29
D11: C45 | F11: Pulverbeschichtet - Schichtdicke 90 ±30 μm - Weißaluminium, RAL 9006 (seidenmatt) | H11: Schaumteil | P11: M7 | Q11: 5.13 | R11: 6.42 | S11: 10.27 | T11: 13.7 | U11: 19.25 | V11: 23.1
D12: 42CrMo4 | F12: ZE - elektrolytisch verzinkt | H12: Spritzgussteil | P12: M8 | Q12: 9.35 | R12: 11.69 | S12: 18,70 | T12: 24.93 | U12: 35.06 | V12: 42.07
D13: X5CrNi18-10 | F13: Harteloxiert - Schichtdicke 25 ±5 μm - Schwarz | H13: Faserverbundteil | P13: M10 | Q13: 18 | R13: 23 | S13: 37 | T13: 49 | U13: 70 | V13: 83
D14: X8CrNiS18-9 | F14: Eloxiert - Schichtdicke 15 ±5 μm - Schwarz | H14: 3D-Druckteil | P14: M12 | Q14: 32 | R14: 40 | S14: 65 | T14: 86 | U14: 121 | V14: 146
D15: EN AW - AlZnMgCu1,5 - T6 | F15: Z - Feuerverzinkt | H15: Schweißgruppe | P15: M14 | Q15: 52 | R15: 65 | S15: 104 | T15: 138 | U15: 194 | V15: 233
D16: EN AW - 6061 | F16: Brüniert | H16: siehe Kauf-/Normteil | P16: M16 | Q16: 81 | R16: 101 | S16: 161 | T16: 215 | U16: 302 | V16: 363
D17: EN AW - 5083 - T6 | F17: Keine Beschichtung | H17: Bearbeitung | P17: M18 | Q17: 112 | R17: 139 | S17: 222 | T17: 296 | U17: 417 | V17: 500
D18: EN AW - 7075 - T6 | F18: ZnNi passiviert oä. | Min. 480h Salzsprühnebel - Soll 720h | Reibwert µ=0.08 bis 0.16 | H18: Beschichtung | P18: M20 | Q18: 157 | R18: 197 | S18: 315 | T18: 420 | U18: 590 | V18: 709
D19: EN AW - 2007 | F19: Pulverbeschichtet - Schichtdicke 150 ±30 μm - Schwarz, SEIDENMATT/20±5%/60DEG | H19: ZSB | P19: M22 | Q19: 215 | R19: 269 | S19: 430 | T19: 574 | U19: 807 | V19: 968
D20: EN AW - 6060 - T6 | H20: Schweißen | P20: M24 | Q20: 272 | R20: 340 | S20: 544 | T20: 726 | U20: 1020 | V20: 1224
D21: EN AW - 6063 - T6 | H21: Profil | P21: M27 | Q21: 400 | R21: 500 | S21: 800 | T21: 1067 | U21: 1500 | V21: 1800
D22: EN AW - 5754 - H111 | P22: M30 | Q22: 542 | R22: 677 | S22: 1083 | T22: 1445 | U22: 2032 | V22: 2438
D23: EN AW - AlMgSi1 | P23: M33 | Q23: 739 | R23: 923 | S23: 1477 | T23: 1969 | U23: 2770 | V23: 3323
D24: EN AW - AlMgSiPb - T6 | P24: M36 | Q24: 948 | R24: 1185 | S24: 1896 | T24: 2528 | U24: 3555 | V24: 4266
D25: EN AW - AlMgSi0,5 - T6 | P25: M39 | Q25: 1229 | R25: 1536 | S25: 2457 | T25: 3276 | U25: 4607 | V25: 5529
D26: EN AW - AlSi1MgMn - T6 | P26: M42 | Q26: 1519 | R26: 1899 | S26: 3038 | T26: 4050 | U26: 5696 | V26: 6835
D27: EN AC - AlSi7Mg - T6 | P27: M45 | Q27: 1898 | R27: 2373 | S27: 3796 | T27: 5062 | U27: 7118 | V27: 8541
D28: EN AC - 42000 - T6 | P28: M48 | Q28: 2282 | R28: 2853 | S28: 4565 | T28: 6086 | U28: 8559 | V28: 10271
D29: EN AC - 42100 - T6 | P29: M52 | Q29: 2954 | R29: 3692 | S29: 5907 | T29: 7876 | U29: 11076 | V29: 13292
D30: PMMA (Polymethylmethacrylat) | P30: M56 | Q30: 3672 | R30: 4591 | S30: 7345 | T30: 9793 | U30: 13772 | V30: 16526
D31: ABS/PMMA | P31: M60 | Q31: 4582 | R31: 5728 | S31: 9164 | T31: 12219 | U31: 17183 | V31: 20619
D32: ABS/PMMA - Graphitschwarz, RAL 9011 (seidenmatt) | P32: M64 | Q32: 5536 | R32: 6920 | S32: 11071 | T32: 14762 | U32: 20759 | V32: 24911
D33: ABS/PMMA - Weißaluminium, RAL 9006 (seidenmatt) | P33: M68 | Q33: 6720 | R33: 8400 | S33: 13440 | T33: 17919 | U33: 25199 | V33: 30239
D34: EPP/PP
D35: PA6 - Schwarz
D36: TPE
D37: EPDM | P37: Gewindegroesse | Q37: M8
D38: GFRP | P38: Festigkeitsklasse | Q38: 8.8
D39: Silikon Flexcomp
D40: Aluminium | P40: Drehmoment in (Nm) | Q40: =INDEX($Q5:$V33,MATCH(Q37,$P5:$P33,0),MATCH(Q38,$Q4:$V4,0)) -> 24.93
...

Sheet Bauteilbenennung
A1: Beispiel: 002_003_001_04_M01_999_999_LTR____________________________YYMMDD_CSI | Q1: Export | S1: Name
R2: Eingabe | S2: Teilenummer | T2: Version | U2: Bezeichnung | V2: Zeichen
A3: 002 | B3: 003 | C3: 001 | D3: 04 | E3: M01 | F3: 999 | G3: 999 | H3: LTR | I3: ___ | J3: YYMMDD | K3: CSI
Q4: =S4&"_"&T4&"_M01_999_999"&"_"&U4&REPT("_",45-LEN(S4&"_"&T4&"_"&U4))&"_YYMMDD_CSI" -> 002_006_905_00_M01_999_999_ZSB_MOTORAUFNAHME______________YYMMDD_CSI | R4: 00200690500 | S4: =_xlfn.CONCAT(LEFT(R4,3),"_",MID(R4,4,3),"_",MID(R4,7,3)) -> 002_006_905 | T4: =RIGHT(R4,2) -> 00 | U4: ZSB_MOTORAUFNAHME | V4: =LEN(Q4) -> 68
K5: CSI | L5: 3 Zeichen Kürzel für Ersteller | Q5: =S5&"_"&T5&"_M01_999_999"&"_"&U5&REPT("_",45-LEN(S5&"_"&T5&"_"&U5))&"_YYMMDD_CSI" -> 002_008_001_01_M01_999_999_BEISPIEL_______________________YYMMDD_CSI | R5: 00200800101 | S5: =_xlfn.CONCAT(LEFT(R5,3),"_",MID(R5,4,3),"_",MID(R5,7,3)) -> 002_008_001 | T5: =RIGHT(R5,2) -> 01 | U5: BEISPIEL | V5: =LEN(Q5) -> 68
Q6: =S6&"_"&T6&"_M01_999_999"&"_"&U6&REPT("_",45-LEN(S6&"_"&T6&"_"&U6))&"_YYMMDD_CSI" -> 002_003_001_01_M01_999_999_ZSB_TRAEGERMODUL_______________YYMMDD_CSI | R6: 00200300101 | S6: =_xlfn.CONCAT(LEFT(R6,3),"_",MID(R6,4,3),"_",MID(R6,7,3)) -> 002_003_001 | T6: =RIGHT(R6,2) -> 01 | U6: ZSB_TRAEGERMODUL | V6: =LEN(Q6) -> 68
J7: YYMMDD | K7: Datum: Year Year Month Month Day Day; Beispiel 240513 | Q7: =S7&"_"&T7&"_M01_999_999"&"_"&U7&REPT("_",45-LEN(S7&"_"&T7&"_"&U7))&"_YYMMDD_CSI" -> 111_222_333_44_M01_999_999_test___________________________YYMMDD_CSI | R7: 11122233344 | S7: =_xlfn.CONCAT(LEFT(R7,3),"_",MID(R7,4,3),"_",MID(R7,7,3)) -> 111_222_333 | T7: =RIGHT(R7,2) -> 44 | U7: test | V7: =LEN(Q7) -> 68
Q8: =S8&"_"&T8&"_M01_999_999"&"_"&U8&REPT("_",45-LEN(S8&"_"&T8&"_"&U8))&"_YYMMDD_CSI" -> 111_222_333_44_M01_999_999_test___________________________YYMMDD_CSI | R8: 11122233344 | S8: =_xlfn.CONCAT(LEFT(R8,3),"_",MID(R8,4,3),"_",MID(R8,7,3)) -> 111_222_333 | T8: =RIGHT(R8,2) -> 44 | U8: test | V8: =LEN(Q8) -> 68
I9: ___ | J9: Trennzeichen: "_" Bauteilnummer immer 68 Zeichen lang | Q9: =S9&"_"&T9&"_M01_999_999"&"_"&U9&REPT("_",45-LEN(S9&"_"&T9&"_"&U9))&"_YYMMDD_CSI" -> 111_222_333_44_M01_999_999_test___________________________YYMMDD_CSI | R9: 11122233344 | S9: =_xlfn.CONCAT(LEFT(R9,3),"_",MID(R9,4,3),"_",MID(R9,7,3)) -> 111_222_333 | T9: =RIGHT(R9,2) -> 44 | U9: test | V9: =LEN(Q9) -> 68
Q10: =S10&"_"&T10&"_M01_999_999"&"_"&U10&REPT("_",45-LEN(S10&"_"&T10&"_"&U10))&"_YYMMDD_CSI" -> 111_222_333_44_M01_999_999_test___________________________YYMMDD_CSI | R10: 11122233344 | S10: =_xlfn.CONCAT(LEFT(R10,3),"_",MID(R10,4,3),"_",MID(R10,7,3)) -> 111_222_333 | T10: =RIGHT(R10,2) -> 44 | U10: test | V10: =LEN(Q10) -> 68
H11: LTR | I11: Beschreibung/Bezeichnung | Q11: =S11&"_"&T11&"_M01_999_999"&"_"&U11&REPT("_",45-LEN(S11&"_"&T11&"_"&U11))&"_YYMMDD_CSI" -> 111_222_333_44_M01_999_999_test___________________________YYMMDD_CSI | R11: 11122233344 | S11: =_xlfn.CONCAT(LEFT(R11,3),"_",MID(R11,4,3),"_",MID(R11,7,3)) -> 111_222_333 | T11: =RIGHT(R11,2) -> 44 | U11: test | V11: =LEN(Q11) -> 68
Q12: =S12&"_"&T12&"_M01_999_999"&"_"&U12&REPT("_",45-LEN(S12&"_"&T12&"_"&U12))&"_YYMMDD_CSI" -> 111_222_333_44_M01_999_999_test___________________________YYMMDD_CSI | R12: 11122233344 | S12: =_xlfn.CONCAT(LEFT(R12,3),"_",MID(R12,4,3),"_",MID(R12,7,3)) -> 111_222_333 | T12: =RIGHT(R12,2) -> 44 | U12: test | V12: =LEN(Q12) -> 68
G13: 999 | H13: Platzhalter | Q13: =S13&"_"&T13&"_M01_999_999"&"_"&U13&REPT("_",45-LEN(S13&"_"&T13&"_"&U13))&"_YYMMDD_CSI" -> 111_222_333_44_M01_999_999_test___________________________YYMMDD_CSI | R13: 11122233344 | S13: =_xlfn.CONCAT(LEFT(R13,3),"_",MID(R13,4,3),"_",MID(R13,7,3)) -> 111_222_333 | T13: =RIGHT(R13,2) -> 44 | U13: test | V13: =LEN(Q13) -> 68
H14: z.b. Kennzeichnung von alternativen Lagen, Versionen etc, | Q14: =S14&"_"&T14&"_M01_999_999"&"_"&U14&REPT("_",45-LEN(S14&"_"&T14&"_"&U14))&"_YYMMDD_CSI" -> 111_222_333_44_M01_999_999_test___________________________YYMMDD_CSI | R14: 11122233344 | S14: =_xlfn.CONCAT(LEFT(R14,3),"_",MID(R14,4,3),"_",MID(R14,7,3)) -> 111_222_333 | T14: =RIGHT(R14,2) -> 44 | U14: test | V14: =LEN(Q14) -> 68
Q15: =S15&"_"&T15&"_M01_999_999"&"_"&U15&REPT("_",45-LEN(S15&"_"&T15&"_"&U15))&"_YYMMDD_CSI" -> 111_222_333_44_M01_999_999_test___________________________YYMMDD_CSI | R15: 11122233344 | S15: =_xlfn.CONCAT(LEFT(R15,3),"_",MID(R15,4,3),"_",MID(R15,7,3)) -> 111_222_333 | T15: =RIGHT(R15,2) -> 44 | U15: test | V15: =LEN(Q15) -> 68
F16: 999 | G16: Platzhalter | Q16: =S16&"_"&T16&"_M01_999_999"&"_"&U16&REPT("_",45-LEN(S16&"_"&T16&"_"&U16))&"_YYMMDD_CSI" -> 111_222_333_44_M01_999_999_test___________________________YYMMDD_CSI | R16: 11122233344 | S16: =_xlfn.CONCAT(LEFT(R16,3),"_",MID(R16,4,3),"_",MID(R16,7,3)) -> 111_222_333 | T16: =RIGHT(R16,2) -> 44 | U16: test | V16: =LEN(Q16) -> 68
Q17: =S17&"_"&T17&"_M01_999_999"&"_"&U17&REPT("_",45-LEN(S17&"_"&T17&"_"&U17))&"_YYMMDD_CSI" -> 111_222_333_44_M01_999_999_test___________________________YYMMDD_CSI | R17: 11122233344 | S17: =_xlfn.CONCAT(LEFT(R17,3),"_",MID(R17,4,3),"_",MID(R17,7,3)) -> 111_222_333 | T17: =RIGHT(R17,2) -> 44 | U17: test | V17: =LEN(Q17) -> 68
E18: M01 | F18: Kennzeichnung Datenstand | Q18: =S18&"_"&T18&"_M01_999_999"&"_"&U18&REPT("_",45-LEN(S18&"_"&T18&"_"&U18))&"_YYMMDD_CSI" -> 111_222_333_44_M01_999_999_test___________________________YYMMDD_CSI | R18: 11122233344 | S18: =_xlfn.CONCAT(LEFT(R18,3),"_",MID(R18,4,3),"_",MID(R18,7,3)) -> 111_222_333 | T18: =RIGHT(R18,2) -> 44 | U18: test | V18: =LEN(Q18) -> 68
F19: "M01"= 3D-Data; "DRW"= 2D, Drawing, DXF etc. | Q19: =S19&"_"&T19&"_M01_999_999"&"_"&U19&REPT("_",45-LEN(S19&"_"&T19&"_"&U19))&"_YYMMDD_CSI" -> 111_222_333_44_M01_999_999_test___________________________YYMMDD_CSI | R19: 11122233344 | S19: =_xlfn.CONCAT(LEFT(R19,3),"_",MID(R19,4,3),"_",MID(R19,7,3)) -> 111_222_333 | T19: =RIGHT(R19,2) -> 44 | U19: test | V19: =LEN(Q19) -> 68
Q20: =S20&"_"&T20&"_M01_999_999"&"_"&U20&REPT("_",45-LEN(S20&"_"&T20&"_"&U20))&"_YYMMDD_CSI" -> 111_222_333_44_M01_999_999_test___________________________YYMMDD_CSI | R20: 11122233344 | S20: =_xlfn.CONCAT(LEFT(R20,3),"_",MID(R20,4,3),"_",MID(R20,7,3)) -> 111_222_333 | T20: =RIGHT(R20,2) -> 44 | U20: test | V20: =LEN(Q20) -> 68
D21: 04 | E21: Revision | Q21: =S21&"_"&T21&"_M01_999_999"&"_"&U21&REPT("_",45-LEN(S21&"_"&T21&"_"&U21))&"_YYMMDD_CSI" -> 111_222_333_44_M01_999_999_test___________________________YYMMDD_CSI | R21: 11122233344 | S21: =_xlfn.CONCAT(LEFT(R21,3),"_",MID(R21,4,3),"_",MID(R21,7,3)) -> 111_222_333 | T21: =RIGHT(R21,2) -> 44 | U21: test | V21: =LEN(Q21) -> 68
E22: Mubea 3F-Regel beachten: Form, Fit & Funkction | Q22: =S22&"_"&T22&"_M01_999_999"&"_"&U22&REPT("_",45-LEN(S22&"_"&T22&"_"&U22))&"_YYMMDD_CSI" -> 111_222_333_44_M01_999_999_test___________________________YYMMDD_CSI | R22: 11122233344 | S22: =_xlfn.CONCAT(LEFT(R22,3),"_",MID(R22,4,3),"_",MID(R22,7,3)) -> 111_222_333 | T22: =RIGHT(R22,2) -> 44 | U22: test | V22: =LEN(Q22) -> 68
E23: Wird eines der "3F" beeinflusst muss revisioniert und eine neue Materialnummer vergeben werden | Q23: =S23&"_"&T23&"_M01_999_999"&"_"&U23&REPT("_",45-LEN(S23&"_"&T23&"_"&U23))&"_YYMMDD_CSI" -> 111_222_333_44_M01_999_999_test___________________________YYMMDD_CSI | R23: 11122233344 | S23: =_xlfn.CONCAT(LEFT(R23,3),"_",MID(R23,4,3),"_",MID(R23,7,3)) -> 111_222_333 | T23: =RIGHT(R23,2) -> 44 | U23: test | V23: =LEN(Q23) -> 68
Q24: =S24&"_"&T24&"_M01_999_999"&"_"&U24&REPT("_",45-LEN(S24&"_"&T24&"_"&U24))&"_YYMMDD_CSI" -> 111_222_333_44_M01_999_999_test___________________________YYMMDD_CSI | R24: 11122233344 | S24: =_xlfn.CONCAT(LEFT(R24,3),"_",MID(R24,4,3),"_",MID(R24,7,3)) -> 111_222_333 | T24: =RIGHT(R24,2) -> 44 | U24: test | V24: =LEN(Q24) -> 68
C25: 001 | D25: Laufende Nummer | Q25: =S25&"_"&T25&"_M01_999_999"&"_"&U25&REPT("_",45-LEN(S25&"_"&T25&"_"&U25))&"_YYMMDD_CSI" -> 111_222_333_44_M01_999_999_test___________________________YYMMDD_CSI | R25: 11122233344 | S25: =_xlfn.CONCAT(LEFT(R25,3),"_",MID(R25,4,3),"_",MID(R25,7,3)) -> 111_222_333 | T25: =RIGHT(R25,2) -> 44 | U25: test | V25: =LEN(Q25) -> 68
D26: ungerade Zahl = linkes Teil, gerade Zahl = rechtes Teil | I26: Wenn nur ein Teil == Links | Q26: =S26&"_"&T26&"_M01_999_999"&"_"&U26&REPT("_",45-LEN(S26&"_"&T26&"_"&U26))&"_YYMMDD_CSI" -> 111_222_333_44_M01_999_999_test___________________________YYMMDD_CSI | R26: 11122233344 | S26: =_xlfn.CONCAT(LEFT(R26,3),"_",MID(R26,4,3),"_",MID(R26,7,3)) -> 111_222_333 | T26: =RIGHT(R26,2) -> 44 | U26: test | V26: =LEN(Q26) -> 68
D27: Füge- oder Schweißgruppen starten immer bei 900 | Q27: =S27&"_"&T27&"_M01_999_999"&"_"&U27&REPT("_",45-LEN(S27&"_"&T27&"_"&U27))&"_YYMMDD_CSI" -> 111_222_333_44_M01_999_999_test___________________________YYMMDD_CSI | R27: 11122233344 | S27: =_xlfn.CONCAT(LEFT(R27,3),"_",MID(R27,4,3),"_",MID(R27,7,3)) -> 111_222_333 | T27: =RIGHT(R27,2) -> 44 | U27: test | V27: =LEN(Q27) -> 68
Q28: =S28&"_"&T28&"_M01_999_999"&"_"&U28&REPT("_",45-LEN(S28&"_"&T28&"_"&U28))&"_YYMMDD_CSI" -> 111_222_333_44_M01_999_999_test___________________________YYMMDD_CSI | R28: 11122233344 | S28: =_xlfn.CONCAT(LEFT(R28,3),"_",MID(R28,4,3),"_",MID(R28,7,3)) -> 111_222_333 | T28: =RIGHT(R28,2) -> 44 | U28: test | V28: =LEN(Q28) -> 68
B29: 003 | C29: Bereich | Q29: =S29&"_"&T29&"_M01_999_999"&"_"&U29&REPT("_",45-LEN(S29&"_"&T29&"_"&U29))&"_YYMMDD_CSI" -> 111_222_333_44_M01_999_999_test___________________________YYMMDD_CSI | R29: 11122233344 | S29: =_xlfn.CONCAT(LEFT(R29,3),"_",MID(R29,4,3),"_",MID(R29,7,3)) -> 111_222_333 | T29: =RIGHT(R29,2) -> 44 | U29: test | V29: =LEN(Q29) -> 68
C30: siehe Stückliste; 003 = Bereich Trägermodul, 008 = Bereich Fahrwerk etc. | Q30: =S30&"_"&T30&"_M01_999_999"&"_"&U30&REPT("_",45-LEN(S30&"_"&T30&"_"&U30))&"_YYMMDD_CSI" -> 111_222_333_44_M01_999_999_test___________________________YYMMDD_CSI | R30: 11122233344 | S30: =_xlfn.CONCAT(LEFT(R30,3),"_",MID(R30,4,3),"_",MID(R30,7,3)) -> 111_222_333 | T30: =RIGHT(R30,2) -> 44 | U30: test | V30: =LEN(Q30) -> 68
A32: 002 | B32: Fahrzeugmodell/Reifegrad
B33: 000 = Pilotserie
B34: 001 = V2.0
B35: 002 = V3.0
B36: 003
B37: 004 = V4.0 Starrachse
B38: Normteile | C38: Sonderlösung | D38: 999_xxx_xxx
B39: Dienstlseistungen | C39: Sonderlösung | D39: 888_xxx_xxx
B41: ZSB | C41: Zusammenbau
B42: SGR | C42: Schweißgruppe
